<?xml version="1.0" ?>
<!-- =================================================================================== -->
<!-- |    This document was autogenerated by xacro from geunwoo.xacro                  | -->
<!-- |    EDITING THIS FILE BY HAND IS NOT RECOMMENDED                                 | -->
<!-- =================================================================================== -->
<robot name="geunwoo">
  <material name="silver">
    <color rgba="0.700 0.700 0.700 1.000"/>
  </material>
  <transmission name="left_wheel_joint_tran">
    <type>transmission_interface/SimpleTransmission</type>
    <joint name="left_wheel_joint">
      <hardwareInterface>hardware_interface/EffortJointInterface</hardwareInterface>
    </joint>
    <actuator name="left_wheel_joint_actr">
      <hardwareInterface>hardware_interface/EffortJointInterface</hardwareInterface>
      <mechanicalReduction>1</mechanicalReduction>
    </actuator>
  </transmission>
  <transmission name="right_wheel_joint_tran">
    <type>transmission_interface/SimpleTransmission</type>
    <joint name="right_wheel_joint">
      <hardwareInterface>hardware_interface/EffortJointInterface</hardwareInterface>
    </joint>
    <actuator name="right_wheel_joint_actr">
      <hardwareInterface>hardware_interface/EffortJointInterface</hardwareInterface>
      <mechanicalReduction>1</mechanicalReduction>
    </actuator>
  </transmission>
  <transmission name="right_caster_joint_tran">
    <type>transmission_interface/SimpleTransmission</type>
    <joint name="right_caster_joint">
      <hardwareInterface>hardware_interface/EffortJointInterface</hardwareInterface>
    </joint>
    <actuator name="right_caster_joint_actr">
      <hardwareInterface>hardware_interface/EffortJointInterface</hardwareInterface>
      <mechanicalReduction>1</mechanicalReduction>
    </actuator>
  </transmission>
  <transmission name="left_caster_joint_tran">
    <type>transmission_interface/SimpleTransmission</type>
    <joint name="left_caster_joint5">
      <hardwareInterface>hardware_interface/EffortJointInterface</hardwareInterface>
    </joint>
    <actuator name="left_caster_joint_actr">
      <hardwareInterface>hardware_interface/EffortJointInterface</hardwareInterface>
      <mechanicalReduction>1</mechanicalReduction>
    </actuator>
  </transmission>
  <gazebo>
    <plugin filename="libgazebo_ros_control.so" name="control"/>
  </gazebo>
  <gazebo reference="base_link">
    <material>Gazebo/Silver</material>
    <mu1>0.2</mu1>
    <mu2>0.2</mu2>
    <self_collide>true</self_collide>
    <gravity>true</gravity>
  </gazebo>
  <gazebo reference="left_wheel">
    <material>Gazebo/Silver</material>
    <mu1>0.2</mu1>
    <mu2>0.2</mu2>
    <self_collide>true</self_collide>
  </gazebo>
  <gazebo reference="right_wheel">
    <material>Gazebo/Silver</material>
    <mu1>0.2</mu1>
    <mu2>0.2</mu2>
    <self_collide>true</self_collide>
  </gazebo>
  <gazebo reference="right_caster">
    <material>Gazebo/Silver</material>
    <mu1>0.2</mu1>
    <mu2>0.2</mu2>
    <self_collide>true</self_collide>
  </gazebo>
  <gazebo reference="left_caster">
    <material>Gazebo/Silver</material>
    <mu1>0.2</mu1>
    <mu2>0.2</mu2>
    <self_collide>true</self_collide>
  </gazebo>
  <link name="base_link">
    <inertial>
      <origin rpy="0 0 0" xyz="-0.10589890450472451 0.004101721807053668 0.2428453449181509"/>
      <mass value="97.68742911120015"/>
      <inertia ixx="5.633563" ixy="0.000389" ixz="0.200866" iyy="4.887417" iyz="-0.000239" izz="5.433869"/>
    </inertial>
    <visual>
      <origin rpy="0 0 0" xyz="0 0 0"/>
      <geometry>
        <mesh filename="file:///home/ryu/ros2_ws/install/hive_gazebo/share/hive_gazebo/meshes/base_link.stl" scale="0.001 0.001 0.001"/>
      </geometry>
      <material name="silver"/>
    </visual>
    <collision>
      <origin rpy="0 0 0" xyz="0 0 0"/>
      <geometry>
        <mesh filename="file:///home/ryu/ros2_ws/install/hive_gazebo/share/hive_gazebo/meshes/base_link.stl" scale="0.001 0.001 0.001"/>
      </geometry>
    </collision>
  </link>
  <link name="left_wheel">
    <inertial>
      <origin rpy="0 0 0" xyz="2.6594023369474935e-07 -0.006200652298741449 -4.894162568547244e-09"/>
      <mass value="1.3260899817774452"/>
      <inertia ixx="0.001415" ixy="-0.0" ixz="0.0" iyy="0.002676" iyz="0.0" izz="0.001415"/>
    </inertial>
    <visual>
      <origin rpy="0 0 0" xyz="1e-06 -0.277578 0.0"/>
      <geometry>
        <mesh filename="file:///home/ryu/ros2_ws/install/hive_gazebo/share/hive_gazebo/meshes/left_wheel_1.stl" scale="0.001 0.001 0.001"/>
      </geometry>
      <material name="silver"/>
    </visual>
    <collision>
      <origin rpy="0 0 0" xyz="1e-06 -0.277578 0.0"/>
      <geometry>
        <mesh filename="file:///home/ryu/ros2_ws/install/hive_gazebo/share/hive_gazebo/meshes/left_wheel_1.stl" scale="0.001 0.001 0.001"/>
      </geometry>
    </collision>
  </link>
  <link name="right_wheel">
    <inertial>
      <origin rpy="0 0 0" xyz="2.5883027950490597e-07 0.006201095560612602 -2.8975644106310483e-10"/>
      <mass value="1.3260894987915728"/>
      <inertia ixx="0.001415" ixy="-0.0" ixz="-0.0" iyy="0.002676" iyz="0.0" izz="0.001415"/>
    </inertial>
    <visual>
      <origin rpy="0 0 0" xyz="1e-06 0.269222 0.0"/>
      <geometry>
        <mesh filename="file:///home/ryu/ros2_ws/install/hive_gazebo/share/hive_gazebo/meshes/right_wheel_1.stl" scale="0.001 0.001 0.001"/>
      </geometry>
      <material name="silver"/>
    </visual>
    <collision>
      <origin rpy="0 0 0" xyz="1e-06 0.269222 0.0"/>
      <geometry>
        <mesh filename="file:///home/ryu/ros2_ws/install/hive_gazebo/share/hive_gazebo/meshes/right_wheel_1.stl" scale="0.001 0.001 0.001"/>
      </geometry>
    </collision>
  </link>
  <link name="right_caster">
    <inertial>
      <origin rpy="0 0 0" xyz="-0.017519612985357313 2.0677910783639675e-07 -0.05240105157186727"/>
      <mass value="1.6117875662608887"/>
      <inertia ixx="0.001424" ixy="-0.0" ixz="-0.000298" iyy="0.001841" iyz="-0.0" izz="0.000923"/>
    </inertial>
    <visual>
      <origin rpy="0 0 0" xyz="0.310001 0.185822 -0.043"/>
      <geometry>
        <mesh filename="file:///home/ryu/ros2_ws/install/hive_gazebo/share/hive_gazebo/meshes/right_caster_1.stl" scale="0.001 0.001 0.001"/>
      </geometry>
      <material name="silver"/>
    </visual>
    <collision>
      <origin rpy="0 0 0" xyz="0.310001 0.185822 -0.043"/>
      <geometry>
        <mesh filename="file:///home/ryu/ros2_ws/install/hive_gazebo/share/hive_gazebo/meshes/right_caster_1.stl" scale="0.001 0.001 0.001"/>
      </geometry>
    </collision>
  </link>
  <link name="left_caster">
    <inertial>
      <origin rpy="0 0 0" xyz="-0.017519612985357313 2.0677910747557426e-07 -0.05240105157186712"/>
      <mass value="1.6117875662608847"/>
      <inertia ixx="0.001424" ixy="-0.0" ixz="-0.000298" iyy="0.001841" iyz="-0.0" izz="0.000923"/>
    </inertial>
    <visual>
      <origin rpy="0 0 0" xyz="0.310001 -0.194178 -0.043"/>
      <geometry>
        <mesh filename="file:///home/ryu/ros2_ws/install/hive_gazebo/share/hive_gazebo/meshes/left_caster_1.stl" scale="0.001 0.001 0.001"/>
      </geometry>
      <material name="silver"/>
    </visual>
    <collision>
      <origin rpy="0 0 0" xyz="0.310001 -0.194178 -0.043"/>
      <geometry>
        <mesh filename="file:///home/ryu/ros2_ws/install/hive_gazebo/share/hive_gazebo/meshes/left_caster_1.stl" scale="0.001 0.001 0.001"/>
      </geometry>
    </collision>
  </link>
  <joint name="left_wheel_joint" type="continuous">
    <origin rpy="0 0 0" xyz="-1e-06 0.277578 0.0"/>
    <parent link="base_link"/>
    <child link="left_wheel"/>
    <axis xyz="0.0 1.0 0.0"/>
  </joint>
  <joint name="right_wheel_joint" type="continuous">
    <origin rpy="0 0 0" xyz="-1e-06 -0.269222 0.0"/>
    <parent link="base_link"/>
    <child link="right_wheel"/>
    <axis xyz="-0.0 -1.0 -0.0"/>
  </joint>
  <joint name="right_caster_joint" type="continuous">
    <origin rpy="0 0 0" xyz="-0.310001 -0.185822 0.043"/>
    <parent link="base_link"/>
    <child link="right_caster"/>
    <axis xyz="0.0 0.0 -1.0"/>
  </joint>
  <joint name="left_caster_joint" type="continuous">
    <origin rpy="0 0 0" xyz="-0.310001 0.194178 0.043"/>
    <parent link="base_link"/>
    <child link="left_caster"/>
    <axis xyz="0.0 0.0 -1.0"/>
  </joint>
</robot>
